[2023-04-25T09:06:44.756+0000] {taskinstance.py:1090} INFO - Dependencies all met for dep_context=non-requeueable deps ti=<TaskInstance: task_on_slack_integration.dummy_task manual__2023-04-25T09:06:44.193535+00:00 [queued]>
[2023-04-25T09:06:44.762+0000] {taskinstance.py:1090} INFO - Dependencies all met for dep_context=requeueable deps ti=<TaskInstance: task_on_slack_integration.dummy_task manual__2023-04-25T09:06:44.193535+00:00 [queued]>
[2023-04-25T09:06:44.762+0000] {taskinstance.py:1288} INFO - 
--------------------------------------------------------------------------------
[2023-04-25T09:06:44.763+0000] {taskinstance.py:1289} INFO - Starting attempt 1 of 1
[2023-04-25T09:06:44.763+0000] {taskinstance.py:1290} INFO - 
--------------------------------------------------------------------------------
[2023-04-25T09:06:44.771+0000] {taskinstance.py:1309} INFO - Executing <Task(PythonOperator): dummy_task> on 2023-04-25 09:06:44.193535+00:00
[2023-04-25T09:06:44.774+0000] {standard_task_runner.py:55} INFO - Started process 2755 to run task
[2023-04-25T09:06:44.777+0000] {standard_task_runner.py:82} INFO - Running: ['***', 'tasks', 'run', 'task_on_slack_integration', 'dummy_task', 'manual__2023-04-25T09:06:44.193535+00:00', '--job-id', '136', '--raw', '--subdir', 'DAGS_FOLDER/Task3.py', '--cfg-path', '/tmp/tmpkb4sfjc3']
[2023-04-25T09:06:44.778+0000] {standard_task_runner.py:83} INFO - Job 136: Subtask dummy_task
[2023-04-25T09:06:44.841+0000] {task_command.py:389} INFO - Running <TaskInstance: task_on_slack_integration.dummy_task manual__2023-04-25T09:06:44.193535+00:00 [running]> on host d51842477fac
[2023-04-25T09:06:44.892+0000] {taskinstance.py:1518} INFO - Exporting the following env vars:
AIRFLOW_CTX_DAG_OWNER=***
AIRFLOW_CTX_DAG_ID=task_on_slack_integration
AIRFLOW_CTX_TASK_ID=dummy_task
AIRFLOW_CTX_EXECUTION_DATE=2023-04-25T09:06:44.193535+00:00
AIRFLOW_CTX_TRY_NUMBER=1
AIRFLOW_CTX_DAG_RUN_ID=manual__2023-04-25T09:06:44.193535+00:00
[2023-04-25T09:06:44.893+0000] {taskinstance.py:1776} ERROR - Task failed with exception
Traceback (most recent call last):
  File "/home/airflow/.local/lib/python3.7/site-packages/airflow/operators/python.py", line 175, in execute
    return_value = self.execute_callable()
  File "/home/airflow/.local/lib/python3.7/site-packages/airflow/operators/python.py", line 192, in execute_callable
    return self.python_callable(*self.op_args, **self.op_kwargs)
  File "/opt/airflow/dags/Task3.py", line 12, in _random_fail
    raise Exception("number less than 50, so fail")
Exception: number less than 50, so fail
[2023-04-25T09:06:44.901+0000] {taskinstance.py:1332} INFO - Marking task as FAILED. dag_id=task_on_slack_integration, task_id=dummy_task, execution_date=20230425T090644, start_date=20230425T090644, end_date=20230425T090644
[2023-04-25T09:06:44.908+0000] {standard_task_runner.py:105} ERROR - Failed to execute job 136 for task dummy_task (number less than 50, so fail; 2755)
[2023-04-25T09:06:44.954+0000] {local_task_job.py:212} INFO - Task exited with return code 1
[2023-04-25T09:06:44.974+0000] {taskinstance.py:2596} INFO - 1 downstream tasks scheduled from follow-on schedule check
